<?xml version="1.0" encoding="utf-8"?>
<!-- This URDF was automatically created by SolidWorks to URDF Exporter! Originally created by Stephen Brawner (brawner@gmail.com) 
     Commit Version: 1.6.0-4-g7f85cfe  Build Version: 1.6.7995.38578
     For more information, please see http://wiki.ros.org/sw_urdf_exporter -->
<robot
  name="z">
  <link
    name="baselink">
    <inertial>
      <origin
        xyz="0.136727936913072 0.163649836381301 0.190786507064757"
        rpy="0 0 0" />
      <mass
        value="1.73988992647191" />
      <inertia
        ixx="0.00476996445378195"
        ixy="6.74938643877778E-06"
        ixz="-9.01366903140054E-05"
        iyy="0.0080616264752367"
        iyz="-5.13396268658168E-05"
        izz="0.00545225217203028" />
    </inertial>
    <visual>
      <origin
        xyz="0 0 0"
        rpy="0 0 0" />
      <geometry>
        <mesh
          filename="package://z/meshes/baselink.STL" />
      </geometry>
      <material
        name="">
        <color
          rgba="0.96078431372549 0.96078431372549 0.964705882352941 1" />
      </material>
    </visual>
    <collision>
      <origin
        xyz="0 0 0"
        rpy="0 0 0" />
      <geometry>
        <mesh
          filename="package://z/meshes/baselink.STL" />
      </geometry>
    </collision>
  </link>
  <link
    name="1">
    <inertial>
      <origin
        xyz="0.0309643572031095 0.0354710496285496 5.84977910139672E-05"
        rpy="0 0 0" />
      <mass
        value="0.887320906853074" />
      <inertia
        ixx="0.0027544697547758"
        ixy="-0.000542280838759937"
        ixz="5.964159452119E-07"
        iyy="0.00653569254499971"
        iyz="6.6389506137881E-08"
        izz="0.00521445541755307" />
    </inertial>
    <visual>
      <origin
        xyz="0 0 0"
        rpy="0 0 0" />
      <geometry>
        <mesh
          filename="package://z/meshes/1.STL" />
      </geometry>
      <material
        name="">
        <color
          rgba="0.96078431372549 0.96078431372549 0.964705882352941 1" />
      </material>
    </visual>
    <collision>
      <origin
        xyz="0 0 0"
        rpy="0 0 0" />
      <geometry>
        <mesh
          filename="package://z/meshes/1.STL" />
      </geometry>
    </collision>
  </link>
  <joint
    name="BasePlate"
    type="continuous">
    <origin
      xyz="0.14154 -0.18886 0.23989"
      rpy="0 0 0" />
    <parent
      link="baselink" />
    <child
      link="1" />
    <axis
      xyz="0 0 0" />
  </joint>
  <link
    name="2">
    <inertial>
      <origin
        xyz="-5.82867087928207E-16 -0.25259101413583 -1.83186799063151E-15"
        rpy="0 0 0" />
      <mass
        value="0.713576578661904" />
      <inertia
        ixx="0.0211358893848965"
        ixy="-2.07489190759413E-17"
        ixz="5.42101086242752E-19"
        iyy="0.000474463194329393"
        iyz="-2.67594648696579E-17"
        izz="0.0216084497083494" />
    </inertial>
    <visual>
      <origin
        xyz="0 0 0"
        rpy="0 0 0" />
      <geometry>
        <mesh
          filename="package://z/meshes/2.STL" />
      </geometry>
      <material
        name="">
        <color
          rgba="0.898039215686275 0.917647058823529 0.929411764705882 1" />
      </material>
    </visual>
    <collision>
      <origin
        xyz="0 0 0"
        rpy="0 0 0" />
      <geometry>
        <mesh
          filename="package://z/meshes/2.STL" />
      </geometry>
    </collision>
  </link>
  <joint
    name="RoboArm1"
    type="continuous">
    <origin
      xyz="-0.075914 0.10968 0"
      rpy="0 0 0" />
    <parent
      link="1" />
    <child
      link="2" />
    <axis
      xyz="0 0 1" />
  </joint>
  <link
    name="3">
    <inertial>
      <origin
        xyz="-1.22124532708767E-15 0.247408985864164 -1.69309011255336E-15"
        rpy="0 0 0" />
      <mass
        value="0.713576578661904" />
      <inertia
        ixx="0.0211358893848965"
        ixy="3.12385750947386E-17"
        ixz="-5.14996031930615E-19"
        iyy="0.000474463194329394"
        iyz="-1.89396567006062E-18"
        izz="0.0216084497083494" />
    </inertial>
    <visual>
      <origin
        xyz="0 0 0"
        rpy="0 0 0" />
      <geometry>
        <mesh
          filename="package://z/meshes/3.STL" />
      </geometry>
      <material
        name="">
        <color
          rgba="0.898039215686275 0.917647058823529 0.929411764705882 1" />
      </material>
    </visual>
    <collision>
      <origin
        xyz="0 0 0"
        rpy="0 0 0" />
      <geometry>
        <mesh
          filename="package://z/meshes/3.STL" />
      </geometry>
    </collision>
  </link>
  <joint
    name="RoboArm2"
    type="continuous">
    <origin
      xyz="0 -0.5 0"
      rpy="0 0 0" />
    <parent
      link="2" />
    <child
      link="3" />
    <axis
      xyz="0 0 0" />
  </joint>
  <link
    name="4">
    <inertial>
      <origin
        xyz="0.0304026812805968 -2.22044604925031E-16 0.00038500000000069"
        rpy="0 0 0" />
      <mass
        value="0.0838934808116942" />
      <inertia
        ixx="0.000151816413673121"
        ixy="2.57498015965307E-19"
        ixz="3.2102548700938E-19"
        iyy="0.000183268023889147"
        iyz="-1.72582963003064E-19"
        izz="0.000113624126912613" />
    </inertial>
    <visual>
      <origin
        xyz="0 0 0"
        rpy="0 0 0" />
      <geometry>
        <mesh
          filename="package://z/meshes/4.STL" />
      </geometry>
      <material
        name="">
        <color
          rgba="0.792156862745098 0.819607843137255 0.933333333333333 1" />
      </material>
    </visual>
    <collision>
      <origin
        xyz="0 0 0"
        rpy="0 0 0" />
      <geometry>
        <mesh
          filename="package://z/meshes/4.STL" />
      </geometry>
    </collision>
  </link>
  <joint
    name="Holder"
    type="continuous">
    <origin
      xyz="0 0.5 0"
      rpy="0 0 0" />
    <parent
      link="3" />
    <child
      link="4" />
    <axis
      xyz="0 0 0" />
  </joint>
  <link
    name="5">
    <inertial>
      <origin
        xyz="0.0815935795033388 0.121674596903559 0.00060174226929377"
        rpy="0 0 0" />
      <mass
        value="0.422769262240391" />
      <inertia
        ixx="0.000137578127893015"
        ixy="-4.85145744427395E-05"
        ixz="7.62704234755628E-08"
        iyy="9.84688868341524E-05"
        iyz="-4.22990670986079E-08"
        izz="0.000206347676360399" />
    </inertial>
    <visual>
      <origin
        xyz="0 0 0"
        rpy="0 0 0" />
      <geometry>
        <mesh
          filename="package://z/meshes/5.STL" />
      </geometry>
      <material
        name="">
        <color
          rgba="0.549019607843137 0.180392156862745 0.180392156862745 1" />
      </material>
    </visual>
    <collision>
      <origin
        xyz="0 0 0"
        rpy="0 0 0" />
      <geometry>
        <mesh
          filename="package://z/meshes/5.STL" />
      </geometry>
    </collision>
  </link>
  <joint
    name="Gripper"
    type="continuous">
    <origin
      xyz="0.03346 0 0.000385"
      rpy="0 0 0" />
    <parent
      link="4" />
    <child
      link="5" />
    <axis
      xyz="0 0 0" />
  </joint>
</robot>